Workbook

Sheet Hoja1
A1: Número | B1: Fecha | C1: Tipo | D1: C.Costo | E1: P. Caja | F1: Código | G1: Proveedor | H1: Tipo | I1: Número | J1: Inst. Financiero | K1: Debe | L1: Haber | M1: Descripción
A2: 2-1-02-02-03 | C2: Proveedores Nacionales | D2: 00000000 | E2: 0000000000 | F2: 8433631 | G2: =+VLOOKUP(F2,Hoja2!$A:$B,2,0) -> JUAN ANTONIO LARA RETAMAL | H2: F4 | I2: 69 | J2: 00000000 | K2: 0 | L2: 500000 | M2: F4/69 JUAN ANTONIO LARA RETAMAL/TRANSPORTE PERSONAL
A3: 5-2-02-09-01 | C3: Movilización | D3: 11110001 | E3: 0000000000 | F3: 8433631 | G3: =+VLOOKUP(F3,Hoja2!$A:$B,2,0) -> JUAN ANTONIO LARA RETAMAL | H3: 00 | I3: 0 | J3: 00000000 | K3: 500000 | L3: 0 | M3: F4/69 JUAN ANTONIO LARA RETAMAL/TRANSPORTE PERSONAL
A4: 2-1-02-02-03 | C4: Proveedores Nacionales | D4: 00000000 | E4: 0000000000 | F4: 8433631 | G4: =+VLOOKUP(F4,Hoja2!$A:$B,2,0) -> JUAN ANTONIO LARA RETAMAL | H4: F4 | I4: 70 | J4: 00000000 | K4: 0 | L4: 690000 | M4: F4/70 JUAN ANTONIO LARA RETAMAL/TRANSPORTE PERSONAL
A5: 5-2-02-09-01 | C5: Movilización | D5: 11110001 | E5: 0000000000 | F5: 8433631 | G5: =+VLOOKUP(F5,Hoja2!$A:$B,2,0) -> JUAN ANTONIO LARA RETAMAL | H5: 00 | I5: 0 | J5: 00000000 | K5: 690000 | L5: 0 | M5: F4/70 JUAN ANTONIO LARA RETAMAL/TRANSPORTE PERSONAL
A6: 2-1-02-02-03 | C6: Proveedores Nacionales | D6: 00000000 | E6: 0000000000 | F6: 19043083 | G6: =+VLOOKUP(F6,Hoja2!$A:$B,2,0) -> JORGE ANTONIO VILLENA ROJAS | H6: F3 | I6: 92 | J6: 00000000 | K6: 0 | L6: 114240 | M6: F3/92 JORGE ANTONIO VILLENA ROJAS/ ARR EXCAVADORA
A7: 5-2-04-17-01 | C7: Servicio Arriendo Maquinaria | D7: 11110001 | E7: 0000000000 | F7: 19043083 | G7: =+VLOOKUP(F7,Hoja2!$A:$B,2,0) -> JORGE ANTONIO VILLENA ROJAS | H7: 00 | I7: 0 | J7: 00000000 | K7: 96000 | L7: 0 | M7: F3/92 JORGE ANTONIO VILLENA ROJAS/ ARR EXCAVADORA
A8: 2-1-02-02-03 | C8: Proveedores Nacionales | D8: 00000000 | E8: 0000000000 | F8: 19043083 | G8: =+VLOOKUP(F8,Hoja2!$A:$B,2,0) -> JORGE ANTONIO VILLENA ROJAS | H8: F3 | I8: 94 | J8: 00000000 | K8: 0 | L8: 719712 | M8: F3/94 JORGE ANTONIO VILLENA ROJAS/ARR EXCAVADORA
A9: 5-2-04-17-01 | C9: Servicio Arriendo Maquinaria | D9: 11110001 | E9: 0000000000 | F9: 19043083 | G9: =+VLOOKUP(F9,Hoja2!$A:$B,2,0) -> JORGE ANTONIO VILLENA ROJAS | H9: 00 | I9: 0 | J9: 00000000 | K9: 604800 | L9: 0 | M9: F3/94 JORGE ANTONIO VILLENA ROJAS/ARR EXCAVADORA
A10: 2-1-02-02-03 | C10: Proveedores Nacionales | D10: 00000000 | E10: 0000000000 | F10: 17185304 | G10: =+VLOOKUP(F10,Hoja2!$A:$B,2,0) -> MARCELO TORRES AYALA | H10: F3 | I10: 168 | J10: 00000000 | K10: 0 | L10: 952000 | M10: F3/168 MARCELO TORRES AYALA/ ARR TRACTOR/OC-876
A11: 5-2-04-17-01 | C11: Servicio Arriendo Maquinaria | D11: 11110001 | E11: 0000000000 | F11: 17185304 | G11: =+VLOOKUP(F11,Hoja2!$A:$B,2,0) -> MARCELO TORRES AYALA | H11: 00 | I11: 0 | J11: 00000000 | K11: 800000 | L11: 0 | M11: F3/168 MARCELO TORRES AYALA/ ARR TRACTOR/OC-876
A12: 2-1-02-02-03 | C12: Proveedores Nacionales | D12: 00000000 | E12: 0000000000 | F12: 17185304 | G12: =+VLOOKUP(F12,Hoja2!$A:$B,2,0) -> MARCELO TORRES AYALA | H12: F3 | I12: 169 | J12: 00000000 | K12: 0 | L12: 952000 | M12: F3/169 MARCELO TORRES AYALA/ ARR TRACTOR/OC-998
A13: 5-2-04-17-01 | C13: Servicio Arriendo Maquinaria | D13: 11110301 | E13: 0000000000 | F13: 17185304 | G13: =+VLOOKUP(F13,Hoja2!$A:$B,2,0) -> MARCELO TORRES AYALA | H13: 00 | I13: 0 | J13: 00000000 | K13: 800000 | L13: 0 | M13: F3/169 MARCELO TORRES AYALA/ ARR TRACTOR/OC-998
... A1048: 5-3-01-02-02 | C1048: Gastos Bancarios | D1048: 00000000 | E1048: 00000000 | F1048: 97036000 | G1048: =+VLOOKUP(F1048,Hoja2!$A:$B,2,0) -> BANCO SANTANDER | H1048: 00 | I1048: 0 | J1048: 00000000 | K1048: 12559 | L1048: 0 | M1048: F4/14459414 BANCO SANTANDER/COM MANTENCION PLAN

Sheet CW20260626C210
A1: COMPROBANTES INGRESADOS
A2: Moneda : 01 Peso Chileno
A3: Tipo : Todos
A4: Rango de Folios : Todos
A5: Fecha : 26/06/2026
A6: Norma: Tributaria e IFRS
A7: Area de Negocio: Todas
A9: Número | B9: Fecha | C9: Tipo | D9: N° Interno | E9: Estado | F9: Descripción
A10: Código Cuenta | C10: Descripción Cuenta | D10: Código | E10: Código | F10: Auxiliar | G10: Documento | I10: Det. de Gasto /
D11: C.Costo | E11: P. Caja | F11: Código | G11: Tipo | H11: Número | I11: Inst. Financiero | J11: Debe | K11: Haber | L11: Descripción
A13: 00000001 | B13: 01/01/2025 | C13: T | D13: 00000001 | E13: Vigente | F13: Reverso de cpbte. N° 00001908, año 2024. DIF TC UF CXP ACCIO
A14: 2-2-03-01-02 | C14: Cuentas Por Pagar Accionistas LP | D14: 00000000 | E14: 0000000000 | F14: 0000000000 | G14: 00 | H14: 0 | I14: 00000000 | J14: 59327301 | K14: 0 | L14: DIF TC UF CXP ACCIONISTA DIC.24
A15: 5-3-02-02-06 | C15: Diferencia de Cambio UF | D15: 00000000 | E15: 0000000000 | F15: 0000000000 | G15: 00 | H15: 0 | I15: 00000000 | J15: 0 | K15: 59327301 | L15: DIF TC UF CXP ACCIONISTA DIC.24
F17: Total Comprobante | J17: 59327301 | K17: 59327301
A19: 00000002 | B19: 01/01/2025 | C19: T | D19: 00000002 | E19: Vigente | F19: Reverso de cpbte. N° 00001903, año 2024. DIF TC ST DICIEMBRE
A20: 1-1-01-03-02 | C20: Banco Santander USD | D20: 00000000 | E20: 0000000000 | F20: 0000000000 | G20: DF | H20: 31122024 | I20: 00000000 | J20: 0 | K20: 420686 | L20: DIF TC ST DICIEMBRE 24
A21: 5-3-02-02-05 | C21: Diferencia de Cambio U$ | D21: 00000000 | E21: 0000000000 | F21: 0000000000 | G21: 00 | H21: 0 | I21: 00000000 | J21: 420686 | K21: 0 | L21: DIF TC ST DICIEMBRE 24
F23: Total Comprobante | J23: 420686 | K23: 420686
A25: 00000003 | B25: 01/01/2025 | C25: T | D25: 00000003 | E25: Vigente | F25: Reverso de cpbte. N° 00001909, año 2024. DIF TC UF DIC.24
A26: 2-2-04-01-16 | C26: CXP Soc Inv La Turbina | D26: 00000000 | E26: 0000000000 | F26: 0000000000 | G26: 00 | H26: 0 | I26: 00000000 | J26: 61406774 | K26: 0 | L26: DIF TC UF TURBINA DIC.24
A27: 2-2-04-01-17 | C27: CXP Soc Inv Centenario | D27: 00000000 | E27: 0000000000 | F27: 0000000000 | G27: 00 | H27: 0 | I27: 00000000 | J27: 61406774 | K27: 0 | L27: DIF TC UF CENTENARIO DIC.24
A28: 5-3-02-02-06 | C28: Diferencia de Cambio UF | D28: 00000000 | E28: 0000000000 | F28: 0000000000 | G28: 00 | H28: 0 | I28: 00000000 | J28: 0 | K28: 61406774 | L28: DIF TC UF TURBINA DIC.24
A29: 5-3-02-02-06 | C29: Diferencia de Cambio UF | D29: 00000000 | E29: 0000000000 | F29: 0000000000 | G29: 00 | H29: 0 | I29: 00000000 | J29: 0 | K29: 61406774 | L29: DIF TC UF CENTENARIO DIC.24
F31: Total Comprobante | J31: 122813548 | K31: 122813548
A33: 00000004 | B33: 17/01/2025 | C33: E | D33: 00000001 | E33: Vigente | F33: PAGO PROVEEDORES $9.010.129
A34: 2-1-02-02-03 | C34: Proveedores Nacionales | D34: 00000000 | E34: 0000000000 | F34: 17185304 | G34: CB | H34: 30072029 | I34: 00000000 | J34: 285600 | K34: 0 | L34: Pago: F3 157 | M34: MARCELO TORRES AYALA
A35: 2-1-02-02-03 | C35: Proveedores Nacionales | D35: 00000000 | E35: 0000000000 | F35: 17185304 | G35: CB | H35: 30072029 | I35: 00000000 | J35: 952000 | K35: 0 | L35: Pago: F3 159 | M35: MARCELO TORRES AYALA
A36: 2-1-02-02-03 | C36: Proveedores Nacionales | D36: 00000000 | E36: 0000000000 | F36: 17185304 | G36: CB | H36: 30072029 | I36: 00000000 | J36: 160650 | K36: 0 | L36: Pago: F3 160 | M36: MARCELO TORRES AYALA
A37: 2-1-02-02-03 | C37: Proveedores Nacionales | D37: 00000000 | E37: 0000000000 | F37: 76307645 | G37: CB | H37: 30072029 | I37: 00000000 | J37: 257007 | K37: 0 | L37: Pago: F3 465673 | M37: INVERSIONES Y COMERCIAL VICHUQUEN SPA
A38: 2-1-02-02-03 | C38: Proveedores Nacionales | D38: 00000000 | E38: 0000000000 | F38: 76488070 | G38: CB | H38: 30072029 | I38: 00000000 | J38: 142705 | K38: 0 | L38: Pago: F3 890355 | M38: INGENIERIA Y SEGURIDAD INDUSTRIAL KS LTDA
A39: 2-1-02-02-03 | C39: Proveedores Nacionales | D39: 00000000 | E39: 0000000000 | F39: 76488070 | G39: CB | H39: 30072029 | I39: 00000000 | J39: 95152 | K39: 0 | L39: Pago: F3 890557 | M39: INGENIERIA Y SEGURIDAD INDUSTRIAL KS LTDA
A40: 2-1-02-02-03 | C40: Proveedores Nacionales | D40: 00000000 | E40: 0000000000 | F40: 76604898 | G40: CB | H40: 30072029 | I40: 00000000 | J40: 131044 | K40: 0 | L40: Pago: F3 6196 | M40: TECNOLOGÍAS EN SEGURIDAD LIMITADA
A41: 2-1-02-02-03 | C41: Proveedores Nacionales | D41: 00000000 | E41: 0000000000 | F41: 76604898 | G41: CB | H41: 30072029 | I41: 00000000 | J41: 132038 | K41: 0 | L41: Pago: F3 6323 | M41: TECNOLOGÍAS EN SEGURIDAD LIMITADA
A42: 2-1-02-02-03 | C42: Proveedores Nacionales | D42: 00000000 | E42: 0000000000 | F42: 76655211 | G42: CB | H42: 30072029 | I42: 00000000 | J42: 499800 | K42: 0 | L42: Pago: F3 9367 | M42: SOCIEDAD COMERCIAL ALESAN LTDA
A43: 2-1-02-02-03 | C43: Proveedores Nacionales | D43: 00000000 | E43: 0000000000 | F43: 76895010 | G43: CB | H43: 30072029 | I43: 00000000 | J43: 442707 | K43: 0 | L43: Pago: F3 8448 | M43: SERVI RIEGO S.A.
A44: 2-1-02-02-03 | C44: Proveedores Nacionales | D44: 00000000 | E44: 0000000000 | F44: 76895010 | G44: CB | H44: 30072029 | I44: 00000000 | J44: 2118200 | K44: 0 | L44: Pago: F3 8454 | M44: SERVI RIEGO S.A.
A45: 2-1-02-02-03 | C45: Proveedores Nacionales | D45: 00000000 | E45: 0000000000 | F45: 76895010 | G45: CB | H45: 30072029 | I45: 00000000 | J45: 649306 | K45: 0 | L45: Pago: F3 8509 | M45: SERVI RIEGO S.A.
... A55: 1-1-01-02-02 | C55: Banco Santander $ | D55: 00000000 | E55: 0000000000 | F55: 0000000000 | G55: CB | H55: 17012025 | I55: 00000000 | J55: 0 | K55: 9010129 | L55: CB 30072029 | M55: Pago varios proveedores
F57: Total Comprobante | J57: 9010129 | K57: 9010129
A59: 00000005 | B59: 10/01/2025 | C59: T | D59: 00000004 | E59: Vigente | F59: F4/69/JUAN ANTONIO LARA RETAMAL
...

Sheet Hoja2
A1: Código | B1: Razón social
A2: 10049125 | B2: JOSE SANDRO CARRASCO URETA
A3: 10105483 | B3: JOSE CELSO DIAZ GONZALEZ
A4: 10174283 | B4: LEOPOLDO ANTONIO URRA CONTRERAS
A5: 10214530 | B5: GERARDO RAMIRO AMARO ROJAS
A6: 10300064 | B6: JUAN ALEXIS REYES SEGURA
A7: 10302821 | B7: MARINA DEL CARMEN SEPULVEDA BARAHONA
A8: 10347469 | B8: PABLO MAGNASO VASQUEZ
A9: 10386651 | B9: ROSAMEL FERNANDEZ BLANCO
A10: 10438993 | B10: EDUARDO ANTONIO NUNEZ JEREZ
A11: 10460349 | B11: DANILO ESTEBAN PINCHEIRA MORALES
A12: 10483031 | B12: ALEJANDRO RODRIGO ARAYA PACHECO
A13: 10626535 | B13: OSCAR RODOLFO ROJAS ARRIAGADA
... A15: 10920668 | B15: CAMILA JORQUIERA
A16: 10927072CT | B16: PAOLA ANDREA ESCOBAR BURGOS
A17: 10940143CT | B17: MARIA LUISA PONCE SEPULVEDA
A18: 10975553 | B18: CLAUDIA MATUS GATICA
A19: 11277519 | B19: Hernan Rigoberto Muñoz Reyes
A20: 11283655 | B20: LUIS IVAN CORDERO CASTRO
A21: 11284640 | B21: ROBERTO ANTONIO NUÑEZ LEIVA
A22: 11372481 | B22: JOSE SAAVEDRA VASQUEZ
A23: 11457402 | B23: LUIS ORLANDO ALBORNOZ MUÑOZ
A24: 11472336 | B24: SERGIO GUZMAN LARRAIN
A25: 11528751 | B25: JOSE HERNAN PLAZA GALLARDO
A26: 11554940 | B26: LUIS GUILLERMO PEÑA VALDES
A27: 11562253 | B27: MARIA INES FAUNDEZ GUAJARDO
A28: 11562337 | B28: CARMEN JIMENA SEPULVEDA MORENO
A29: 11676150 | B29: ALICIA DEL CARMEN VILLAGRA LUPAYANTE
... A45: 12587598 | B45: MAURICIO GRACIA RAMIREZ
A46: 12725734CT | B46: SUSSY ALEJANDRA ASTORGA RIVERAS
A47: 12725773 | B47: MAXIMILIANO FABIAN FLORES ARAYA
A48: 12725936 | B48: CLAUDIA ANDREA REYES SEGURA
A49: 12783019 | B49: PEDRO VIDAL MOYA DIAZ
A50: 12787535 | B50: DAVID TEJO CIFUENTES
A51: 12883789 | B51: LUIS IGNACIO MANQUEHUAL
A52: 12912271 | B52: RODRIGO ALFONSO ALARCON CORRALES
A53: 12963368 | B53: PABLO ANDRES CONTRERAS VASQUEZ
A54: 13051415 | B54: JULIAN ANDRES MIRANDA OSSES
A55: 13053998 | B55: CYNTHIA FRANCESCA ALVEAR HENRIQUEZ
A56: 13100069 | B56: CARLOS ECHAGUE PAVEZ
...
