Workbook

Sheet Hoja1
A1: Código Cuenta | C1: Descripción Cuenta | D1: C.Costo | E1: P. Caja | F1: Código | G1: PROVEEDOR | H1: Tipo | I1: Número | J1: Inst. Financiero | K1: Debe | L1: Haber | M1: Descripción
A2: 2-1-02-02-03 | C2: Proveedores Nacionales | D2: 00000000 | E2: 0000000000 | F2: 76411321 | G2: =+VLOOKUP(F2,Hoja2!$A:$B,2,0) -> CGE S.A | H2: F3 | I2: 22937072 | J2: 00000000 | K2: 0 | L2: 3629790 | M2: F3/22937072 CGE S.A/SERVICIO ELECTRICO/CLIENTE-5481635
A3: 5-2-04-06-01 | C3: Electricidad | D3: 11060001 | E3: 0000000000 | F3: 76411321 | G3: =+VLOOKUP(F3,Hoja2!$A:$B,2,0) -> CGE S.A | H3: 00 | I3: 0 | J3: 00000000 | K3: 3061474 | L3: 0 | M3: F3/22937072 CGE S.A/SERVICIO ELECTRICO/CLIENTE-5481635
A4: 2-1-02-02-03 | C4: Proveedores Nacionales | D4: 00000000 | E4: 0000000000 | F4: 76411321 | G4: =+VLOOKUP(F4,Hoja2!$A:$B,2,0) -> CGE S.A | H4: F3 | I4: 22941620 | J4: 00000000 | K4: 0 | L4: 2071002 | M4: F3/22941620 CGE S.A/SERVICIO ELECTRICO/CLIENTE-1582722
A5: 5-2-04-06-01 | C5: Electricidad | D5: 11050001 | E5: 0000000000 | F5: 76411321 | G5: =+VLOOKUP(F5,Hoja2!$A:$B,2,0) -> CGE S.A | H5: 00 | I5: 0 | J5: 00000000 | K5: 1746210 | L5: 0 | M5: F3/22941620 CGE S.A/SERVICIO ELECTRICO/CLIENTE-1582722
A6: 2-1-02-02-03 | C6: Proveedores Nacionales | D6: 00000000 | E6: 0000000000 | F6: 77462311 | G6: =+VLOOKUP(F6,Hoja2!$A:$B,2,0) -> AGROMAQ SPA | H6: F3 | I6: 78 | J6: 00000000 | K6: 0 | L6: 1904000 | M6: F3/78 AGROMAQ/SERV TRACTORES/OC-3155
A7: 5-2-04-17-01 | C7: Servicio Arriendo Maquinaria | D7: 11050001 | E7: 0000000000 | F7: 77462311 | G7: =+VLOOKUP(F7,Hoja2!$A:$B,2,0) -> AGROMAQ SPA | H7: 00 | I7: 0 | J7: 00000000 | K7: 1600000 | L7: 0 | M7: F3/78 AGROMAQ/SERV TRACTORES/OC-3155
A8: 2-1-02-02-03 | C8: Proveedores Nacionales | D8: 00000000 | E8: 0000000000 | F8: 77079116 | G8: =+VLOOKUP(F8,Hoja2!$A:$B,2,0) -> MINIMACK SPA | H8: F3 | I8: 208 | J8: 00000000 | K8: 0 | L8: 214200 | M8: F3/208 MINIMACK/ TRASLADO TRACTOR/OC-3202
A9: 5-2-04-12-01 | C9: Fletes | D9: 11050001 | E9: 0000000000 | F9: 77079116 | G9: =+VLOOKUP(F9,Hoja2!$A:$B,2,0) -> MINIMACK SPA | H9: 00 | I9: 0 | J9: 00000000 | K9: 180000 | L9: 0 | M9: F3/208 MINIMACK/ TRASLADO TRACTOR/OC-3202
A10: 2-1-02-02-03 | C10: Proveedores Nacionales | D10: 00000000 | E10: 0000000000 | F10: 12413175 | G10: =+VLOOKUP(F10,Hoja2!$A:$B,2,0) -> JOANNA ISABEL RIQUELME TRUJILLO | H10: F3 | I10: 806 | J10: 00000000 | K10: 0 | L10: 137145 | M10: F3/806 JOANNA ISABEL RIQUELME/CONTROL PLAGAS DIC
A11: 5-2-04-07-01 | C11: Servicio de Aseo | D11: 11130001 | E11: 0000000000 | F11: 12413175 | G11: =+VLOOKUP(F11,Hoja2!$A:$B,2,0) -> JOANNA ISABEL RIQUELME TRUJILLO | H11: 00 | I11: 0 | J11: 00000000 | K11: 115248 | L11: 0 | M11: F3/806 JOANNA ISABEL RIQUELME/CONTROL PLAGAS DIC
A12: 2-1-02-02-03 | C12: Proveedores Nacionales | D12: 00000000 | E12: 0000000000 | F12: 76081128 | G12: =+VLOOKUP(F12,Hoja2!$A:$B,2,0) -> TRANSPORTES Y SERVICIOS BOZO &amp; BOZO LIMITADA | H12: F3 | I12: 2086 | J12: 00000000 | K12: 0 | L12: 30000 | M12: F3/2086 TRANSPORTES Y SERV BOZO &amp | N12: BOZO/REP NEUMATICO
A13: 5-2-03-05-02 | C13: Mant. y repuestos Maquinaria | D13: 11130001 | E13: 0000000000 | F13: 76081128 | G13: =+VLOOKUP(F13,Hoja2!$A:$B,2,0) -> TRANSPORTES Y SERVICIOS BOZO &amp; BOZO LIMITADA | H13: 00 | I13: 0 | J13: 00000000 | K13: 25210 | L13: 0 | M13: F3/2086 TRANSPORTES Y SERV BOZO &amp | N13: BOZO/REP NEUMATICO
A14: 2-1-02-02-03 | C14: Proveedores Nacionales | D14: 00000000 | E14: 0000000000 | F14: 77538629 | G14: =+VLOOKUP(F14,Hoja2!$A:$B,2,0) -> DISTRIBUIDORA VILLASECA SPA | H14: F3 | I14: 6385 | J14: 00000000 | K14: 0 | L14: 74000 | M14: F3/6385 DISTRIBUIDORA VILLASECA/AUTOGAS 15 KG
A15: 5-2-04-11-01 | C15: Gas | D15: 11050217 | E15: 0000000000 | F15: 77538629 | G15: =+VLOOKUP(F15,Hoja2!$A:$B,2,0) -> DISTRIBUIDORA VILLASECA SPA | H15: 00 | I15: 0 | J15: 00000000 | K15: 62185 | L15: 0 | M15: F3/6385 DISTRIBUIDORA VILLASECA/AUTOGAS 15 KG
A16: 2-1-02-02-03 | C16: Proveedores Nacionales | D16: 00000000 | E16: 0000000000 | F16: 77538629 | G16: =+VLOOKUP(F16,Hoja2!$A:$B,2,0) -> DISTRIBUIDORA VILLASECA SPA | H16: F3 | I16: 6399 | J16: 00000000 | K16: 0 | L16: 74000 | M16: F3/6399 DISTRIBUIDORA VILLASECA/AUTOGAS 15 KG
A17: 5-2-04-11-01 | C17: Gas | D17: 11050217 | E17: 0000000000 | F17: 77538629 | G17: =+VLOOKUP(F17,Hoja2!$A:$B,2,0) -> DISTRIBUIDORA VILLASECA SPA | H17: 00 | I17: 0 | J17: 00000000 | K17: 62185 | L17: 0 | M17: F3/6399 DISTRIBUIDORA VILLASECA/AUTOGAS 15 KG
A18: 2-1-02-02-03 | C18: Proveedores Nacionales | D18: 00000000 | E18: 0000000000 | F18: 76604898 | G18: =+VLOOKUP(F18,Hoja2!$A:$B,2,0) -> TECNOLOGIAS EN SEGURIDAD LTDA. | H18: F3 | I18: 6408 | J18: 00000000 | K18: 0 | L18: 178304 | M18: F3/6408 TECNOLOGIAS EN SEGURIDAD/SERV ALPHA
A19: 5-2-04-09-01 | C19: Seguridad | D19: 11130001 | E19: 0000000000 | F19: 76604898 | G19: =+VLOOKUP(F19,Hoja2!$A:$B,2,0) -> TECNOLOGIAS EN SEGURIDAD LTDA. | H19: 00 | I19: 0 | J19: 00000000 | K19: 149835 | L19: 0 | M19: F3/6408 TECNOLOGIAS EN SEGURIDAD/SERV ALPHA
A20: 2-1-02-02-03 | C20: Proveedores Nacionales | D20: 00000000 | E20: 0000000000 | F20: 77538629 | G20: =+VLOOKUP(F20,Hoja2!$A:$B,2,0) -> DISTRIBUIDORA VILLASECA SPA | H20: F3 | I20: 6412 | J20: 00000000 | K20: 0 | L20: 74000 | M20: F3/6412 DISTRIBUIDORA VILLASECA/AUTOGAS 15 KG
A21: 5-2-04-11-01 | C21: Gas | D21: 11050217 | E21: 0000000000 | F21: 77538629 | G21: =+VLOOKUP(F21,Hoja2!$A:$B,2,0) -> DISTRIBUIDORA VILLASECA SPA | H21: 00 | I21: 0 | J21: 00000000 | K21: 62185 | L21: 0 | M21: F3/6412 DISTRIBUIDORA VILLASECA/AUTOGAS 15 KG
A22: 2-1-02-02-03 | C22: Proveedores Nacionales | D22: 00000000 | E22: 0000000000 | F22: 76099405 | G22: =+VLOOKUP(F22,Hoja2!$A:$B,2,0) -> SERVICIOS DE CONECTIVIDAD RURAL SPA | H22: F3 | I22: 24436 | J22: 00000000 | K22: 0 | L22: 137148 | M22: F3/24436 SERVICIOS DE CONECTIVIDAD RURAL/INTERNET
A23: 5-2-04-01-01 | C23: Comunicaciones | D23: 11130001 | E23: 0000000000 | F23: 76099405 | G23: =+VLOOKUP(F23,Hoja2!$A:$B,2,0) -> SERVICIOS DE CONECTIVIDAD RURAL SPA | H23: 00 | I23: 0 | J23: 00000000 | K23: 115250 | L23: 0 | M23: F3/24436 SERVICIOS DE CONECTIVIDAD RURAL/INTERNET
A24: 2-1-02-02-03 | C24: Proveedores Nacionales | D24: 00000000 | E24: 0000000000 | F24: 97006000 | G24: =+VLOOKUP(F24,Hoja2!$A:$B,2,0) -> BANCO DE CREDITO E INVERSIONES | H24: F3 | I24: 27305221 | J24: 00000000 | K24: 0 | L24: 91431 | M24: F3/27305221 BANCO DE CREDITO E INV/COMISION MANT CTA CTE
A25: 5-3-01-02-02 | C25: Gastos Bancarios | D25: 00000000 | E25: 0000000000 | F25: 97006000 | G25: =+VLOOKUP(F25,Hoja2!$A:$B,2,0) -> BANCO DE CREDITO E INVERSIONES | H25: 00 | I25: 0 | J25: 00000000 | K25: 76833 | L25: 0 | M25: F3/27305221 BANCO DE CREDITO E INV/COMISION MANT CTA CTE
... A84: 5-2-03-01-01 | C84: Materiales de Oficina | D84: 11050001 | E84: 0000000000 | F84: 96556940 | G84: =+VLOOKUP(F84,Hoja2!$A:$B,2,0) -> PROVEEDORES INTEGRALES PRISA S.A | H84: 00 | I84: 0 | J84: 00000000 | K84: 69927 | L84: 0 | M84: F3/13649888 PROVEEDORES INTEGRALES PRISA/CUADERNO/OC-3236
A85: 2-1-02-02-03 | C85: Proveedores Nacionales | D85: 00000000 | E85: 0000000000 | F85: 76081128 | G85: =+VLOOKUP(F85,Hoja2!$A:$B,2,0) -> TRANSPORTES Y SERVICIOS BOZO &amp; BOZO LIMITADA | H85: F3 | I85: 2103 | J85: 00000000 | K85: 0 | L85: 44000 | M85: F3/2103 TRANSPORTES Y SERV BOZO &amp | N85: BOZO/REP NEUMATICO
A86: 5-2-03-05-02 | C86: Mant. y repuestos Maquinaria | D86: 11050001 | E86: 0000000000 | F86: 76081128 | G86: =+VLOOKUP(F86,Hoja2!$A:$B,2,0) -> TRANSPORTES Y SERVICIOS BOZO &amp; BOZO LIMITADA | H86: 00 | I86: 0 | J86: 00000000 | K86: 36975 | L86: 0 | M86: F3/2103 TRANSPORTES Y SERV BOZO &amp | N86: BOZO/REP NEUMATICO
A87: 2-1-02-02-03 | C87: Proveedores Nacionales | D87: 00000000 | E87: 0000000000 | F87: 76081128 | G87: =+VLOOKUP(F87,Hoja2!$A:$B,2,0) -> TRANSPORTES Y SERVICIOS BOZO &amp; BOZO LIMITADA | H87: F3 | I87: 2104 | J87: 00000000 | K87: 0 | L87: 41000 | M87: F3/2104 TRANSPORTES Y SERV BOZO &amp | N87: BOZO/VULCANIZADO
A88: 5-2-03-05-02 | C88: Mant. y repuestos Maquinaria | D88: 11050001 | E88: 0000000000 | F88: 76081128 | G88: =+VLOOKUP(F88,Hoja2!$A:$B,2,0) -> TRANSPORTES Y SERVICIOS BOZO &amp; BOZO LIMITADA | H88: 00 | I88: 0 | J88: 00000000 | K88: 34454 | L88: 0 | M88: F3/2104 TRANSPORTES Y SERV BOZO &amp | N88: BOZO/VULCANIZADO
A89: 2-1-02-02-03 | C89: Proveedores Nacionales | D89: 00000000 | E89: 0000000000 | F89: 77538629 | G89: =+VLOOKUP(F89,Hoja2!$A:$B,2,0) -> DISTRIBUIDORA VILLASECA SPA | H89: F3 | I89: 6524 | J89: 00000000 | K89: 0 | L89: 74000 | M89: F3/6524 DISTRIBUIDORA VILLASECA/ AUTOGAS 15 KG
A90: 5-2-04-11-01 | C90: Gas | D90: 11050217 | E90: 0000000000 | F90: 77538629 | G90: =+VLOOKUP(F90,Hoja2!$A:$B,2,0) -> DISTRIBUIDORA VILLASECA SPA | H90: 00 | I90: 0 | J90: 00000000 | K90: 62185 | L90: 0 | M90: F3/6524 DISTRIBUIDORA VILLASECA/ AUTOGAS 15 KG
A91: 2-1-02-02-03 | C91: Proveedores Nacionales | D91: 00000000 | E91: 0000000000 | F91: 77538629 | G91: =+VLOOKUP(F91,Hoja2!$A:$B,2,0) -> DISTRIBUIDORA VILLASECA SPA | H91: F3 | I91: 6533 | J91: 00000000 | K91: 0 | L91: 74000 | M91: F3/6533 DISTRIBUIDORA VILLASECA/ AUTOGAS 15 KG
A92: 5-2-04-11-01 | C92: Gas | D92: 11050217 | E92: 0000000000 | F92: 77538629 | G92: =+VLOOKUP(F92,Hoja2!$A:$B,2,0) -> DISTRIBUIDORA VILLASECA SPA | H92: 00 | I92: 0 | J92: 00000000 | K92: 62185 | L92: 0 | M92: F3/6533 DISTRIBUIDORA VILLASECA/ AUTOGAS 15 KG
A93: 2-1-02-02-03 | C93: Proveedores Nacionales | D93: 00000000 | E93: 0000000000 | F93: 97036000 | G93: =+VLOOKUP(F93,Hoja2!$A:$B,2,0) -> BANCO SANTANDER | H93: F4 | I93: 13200515 | J93: 00000000 | K93: 0 | L93: 1269 | M93: F4/13200515 BANCO SANTANDER/COMISION MANTENCION PLAN
A94: 5-3-01-02-02 | C94: Gastos Bancarios | D94: 00000000 | E94: 0000000000 | F94: 97036000 | G94: =+VLOOKUP(F94,Hoja2!$A:$B,2,0) -> BANCO SANTANDER | H94: 00 | I94: 0 | J94: 00000000 | K94: 1269 | L94: 0 | M94: F4/13200515 BANCO SANTANDER/COMISION MANTENCION PLAN
A95: 2-1-02-02-03 | C95: Proveedores Nacionales | D95: 00000000 | E95: 0000000000 | F95: 97036000 | G95: =+VLOOKUP(F95,Hoja2!$A:$B,2,0) -> BANCO SANTANDER | H95: F3 | I95: 50423021 | J95: 00000000 | K95: 0 | L95: 13636 | M95: F3/50423021 BANCO SANTANDER/COMISION MANTENCION PLAN
A96: 5-3-01-02-02 | C96: Gastos Bancarios | D96: 00000000 | E96: 0000000000 | F96: 97036000 | G96: =+VLOOKUP(F96,Hoja2!$A:$B,2,0) -> BANCO SANTANDER | H96: 00 | I96: 0 | J96: 00000000 | K96: 11458 | L96: 0 | M96: F3/50423021 BANCO SANTANDER/COMISION MANTENCION PLAN
A97: 2-1-02-02-03 | C97: Proveedores Nacionales | D97: 00000000 | E97: 0000000000 | F97: 77462311 | G97: =+VLOOKUP(F97,Hoja2!$A:$B,2,0) -> AGROMAQ SPA | H97: F3 | I97: 98 | J97: 00000000 | K97: 0 | L97: 1904000 | M97: F3/98 AGROMAQ/ SERV ARR TRACTORES/OC-3089
A98: 5-2-04-17-01 | C98: Servicio Arriendo Maquinaria | D98: 11050001 | E98: 0000000000 | F98: 77462311 | G98: =+VLOOKUP(F98,Hoja2!$A:$B,2,0) -> AGROMAQ SPA | H98: 00 | I98: 0 | J98: 00000000 | K98: 1600000 | L98: 0 | M98: F3/98 AGROMAQ/ SERV ARR TRACTORES/OC-3089
...

Sheet CW202606265FBB
A1: COMPROBANTES INGRESADOS
A2: Moneda : 01 Peso Chileno
A3: Tipo : Todos
A4: Rango de Folios : Todos
A5: Fecha : 26/06/2026
A6: Norma: Tributaria e IFRS
A7: Area de Negocio: Todas
A9: Número | B9: Fecha | C9: Tipo | D9: N° Interno | E9: Estado | F9: Descripción
A10: Código Cuenta | C10: Descripción Cuenta | D10: Código | E10: Código | F10: Auxiliar | G10: Documento | I10: Det. de Gasto /
D11: C.Costo | E11: P. Caja | F11: Código | G11: Tipo | H11: Número | I11: Inst. Financiero | J11: Debe | K11: Haber | L11: Descripción
A13: 00000001 | B13: 08/01/2025 | C13: E | D13: 00000001 | E13: Vigente | F13: Pago proveedores $5.515.700
A14: 2-1-02-02-03 | C14: Proveedores Nacionales | D14: 00000000 | E14: 0000000000 | F14: 77512542 | G14: TR | H14: 8012025 | I14: 00000000 | J14: 4795700 | K14: 0 | L14: F-20
A15: 2-1-02-02-06 | C15: Honorarios Por Pagar | D15: 00000000 | E15: 0000000000 | F15: 18658379 | G15: TR | H15: 8012025 | I15: 00000000 | J15: 720000 | K15: 0 | L15: BH 30
A16: 1-1-01-02-02 | C16: Banco Santander $ | D16: 00000000 | E16: 0000000000 | F16: 0000000000 | G16: CB | H16: 8012025 | I16: 00000000 | J16: 0 | K16: 4795700 | L16: Pago proveedores $5.515.700
A17: 1-1-01-02-02 | C17: Banco Santander $ | D17: 00000000 | E17: 0000000000 | F17: 0000000000 | G17: CB | H17: 8012025 | I17: 00000000 | J17: 0 | K17: 720000 | L17: Pago proveedores $5.515.700
F19: Total Comprobante | J19: 5515700 | K19: 5515700
A21: 00000002 | B21: 17/01/2025 | C21: E | D21: 00000002 | E21: Vigente | F21: PAGO PROVEEDORES $2.738.578
A22: 2-1-02-02-03 | C22: Proveedores Nacionales | D22: 00000000 | E22: 0000000000 | F22: 71430300 | G22: CB | H22: 26072032 | I22: 00000000 | J22: 106624 | K22: 0 | L22: Pago: F3 43219 | M22: FUNDACION CHILENA DE CULTURA
A23: 2-1-02-02-03 | C23: Proveedores Nacionales | D23: 00000000 | E23: 0000000000 | F23: 76855237 | G23: CB | H23: 26072032 | I23: 00000000 | J23: 617001 | K23: 0 | L23: Pago: P1 59181 | M23: COMERCIAL TODO AGRO SPA
A24: 2-1-02-02-03 | C24: Proveedores Nacionales | D24: 00000000 | E24: 0000000000 | F24: 77079116 | G24: CB | H24: 26072032 | I24: 00000000 | J24: 583100 | K24: 0 | L24: Pago: F3 202 | M24: MINIMACK SPA
A25: 2-1-02-02-03 | C25: Proveedores Nacionales | D25: 00000000 | E25: 0000000000 | F25: 77538629 | G25: CB | H25: 26072032 | I25: 00000000 | J25: 37000 | K25: 0 | L25: Pago: F3 6237 | M25: DISTRIBUIDORA VILLASECA SPA
A26: 2-1-02-02-03 | C26: Proveedores Nacionales | D26: 00000000 | E26: 0000000000 | F26: 77538629 | G26: CB | H26: 26072032 | I26: 00000000 | J26: 74000 | K26: 0 | L26: Pago: F3 6241 | M26: DISTRIBUIDORA VILLASECA SPA
A27: 2-1-02-02-03 | C27: Proveedores Nacionales | D27: 00000000 | E27: 0000000000 | F27: 78866720 | G27: CB | H27: 26072032 | I27: 00000000 | J27: 271082 | K27: 0 | L27: Pago: F3 922539 | M27: INVERSIONES Y COMERCIAL TRANCURA LIMITADA
A28: 2-1-02-02-03 | C28: Proveedores Nacionales | D28: 00000000 | E28: 0000000000 | F28: 79736770 | G28: CB | H28: 26072032 | I28: 00000000 | J28: 922000 | K28: 0 | L28: Pago: F3 78696 | M28: COMERCIAL CALAMA S.A.
A29: 2-1-02-02-03 | C29: Proveedores Nacionales | D29: 00000000 | E29: 0000000000 | F29: 91502000 | G29: CB | H29: 26072032 | I29: 00000000 | J29: 127771 | K29: 0 | L29: Pago: F3 4619581 | M29: SALINAS Y FABRES S.A.
A30: 1-1-01-02-06 | C30: Banco BCI $ | D30: 00000000 | E30: 0000000000 | F30: 0000000000 | G30: CB | H30: 17012025 | I30: 00000000 | J30: 0 | K30: 2738578 | L30: CB 17012025 | M30: Pago varios proveedores
F32: Total Comprobante | J32: 2738578 | K32: 2738578
A34: 00000003 | B34: 13/01/2025 | C34: E | D34: 00000003 | E34: Vigente | F34: Pago CGE $3.629.800
A35: 1-1-01-02-02 | C35: Banco Santander $ | D35: 00000000 | E35: 0000000000 | F35: 0000000000 | G35: CB | H35: 13012025 | I35: 00000000 | J35: 0 | K35: 3629800 | L35: Pago CGE $3.629.800
A36: 2-1-02-02-03 | C36: Proveedores Nacionales | D36: 00000000 | E36: 0000000000 | F36: 76411321 | G36: TR | H36: 13012025 | I36: 00000000 | J36: 3629790 | K36: 0 | L36: F-22937072
A37: 5-2-04-06-01 | C37: Electricidad | D37: 11050001 | E37: 0000000000 | F37: 0000000000 | G37: 00 | H37: 0 | I37: 00000000 | J37: 10 | K37: 0 | L37: Ajuste pago $3.629.800
F39: Total Comprobante | J39: 3629800 | K39: 3629800
A41: 00000004 | B41: 13/01/2025 | C41: E | D41: 00000004 | E41: Vigente | F41: Pago CGE $2.071.000
A42: 1-1-01-02-02 | C42: Banco Santander $ | D42: 00000000 | E42: 0000000000 | F42: 0000000000 | G42: CB | H42: 13012025 | I42: 00000000 | J42: 0 | K42: 2071000 | L42: Pago CGE $2.071.000
A43: 2-1-02-02-03 | C43: Proveedores Nacionales | D43: 00000000 | E43: 0000000000 | F43: 76411321 | G43: TR | H43: 13012025 | I43: 00000000 | J43: 2071002 | K43: 0 | L43: F-22941620
A44: 5-2-04-06-01 | C44: Electricidad | D44: 11050001 | E44: 0000000000 | F44: 0000000000 | G44: 00 | H44: 0 | I44: 00000000 | J44: 0 | K44: 2 | L44: Ajuste pago $2.071.000
F46: Total Comprobante | J46: 2071002 | K46: 2071002
A48: 00000005 | B48: 10/01/2025 | C48: T | D48: 00000001 | E48: Vigente | F48: F3/22937072/CGE S.A
A49: 2-1-02-02-03 | C49: Proveedores Nacionales | D49: 00000000 | E49: 0000000000 | F49: 76411321 | G49: F3 | H49: 22937072 | I49: 00000000 | J49: 0 | K49: 3629790 | L49: F3/22937072 CGE S.A/SERVICIO ELECTRICO/CLIENTE-5481635
A50: 1-1-07-01-01 | C50: IVA Crédito Fiscal | D50: 00000000 | E50: 0000000000 | F50: 0000000000 | G50: 00 | H50: 0 | I50: 00000000 | J50: 568316 | K50: 0 | L50: F3/22937072 CGE S.A/SERVICIO ELECTRICO/CLIENTE-5481635
...

Sheet Hoja2
A1: Código | B1: Razón social
A2: 10049125 | B2: JOSE SANDRO CARRASCO URETA
A3: 10131083 | B3: JUAN MANUEL MORALES VERGARA
A4: 10158144 | B4: VICENTE ALEJANDRO PINA URZUA
A5: 10162014 | B5: ALFONSO GONZALO VALENZUELA CORREA
A6: 10274720 | B6: PAULO JOSE AMADO ROMO
A7: 10300064 | B7: JUAN ALEXIS REYES SEGURA
A8: 10302821 | B8: MARINA DEL CARMEN SEPULVEDA BARAHONA
A9: 10347469 | B9: PABLO MAGNASCO VASQUEZ
A10: 10427844 | B10: LUIS ARTURO LIZANA PENA
A11: 10435173 | B11: DINO FRANCO PEÑALOZA MOLINA
A12: 10453671 | B12: MANUEL JESUS VALDES ACEVEDO
A13: 10460642 | B13: JOSE RODRIGO PAVEZ MORENO
... A20: 10898803 | B20: MARIA ANDREA PIZARRO VELIZ
A21: 10927072CT | B21: PAOLA ANDREA ESCOBAR BURGOS
A22: 10940143CT | B22: MARIA LUISA PONCE SEPULVEDA
A23: 10975553 | B23: CLAUDIA MATUS GATICA
A24: 11057106 | B24: MAGALY DEL CARMEN RIVERA CANTILLANA
A25: 11143836 | B25: ALEX ANTONIO FUENZALIDA NUÑEZ
A26: 11277337 | B26: RAFAEL PATRICIO PINA CAMPOS
A27: 11283655 | B27: LUIS IVAN CORDERO CASTRO
A28: 11484217 | B28: LUISA MEDINA
A29: 11528751 | B29: JOSE HERNAN PLAZA GALLARDO
A30: 11551345 | B30: HUGO ERNESTO HENRIQUEZ LASTRA
A31: 11554940 | B31: LUIS GUILLERMO PEÑA VALDES
A32: 11555517 | B32: SOLERCIO ANTONIO PASTENE TORRES
A33: 11562253 | B33: MARIA INES FAUNDEZ GUAJARDO
A34: 11759075 | B34: ULISES RODRIGUEZ ZAMORANO
... A44: 12695363 | B44: David Soto Contreras
A45: 12725734CT | B45: SUSSY ALEJANDRA ASTORGA RIVERAS
A46: 12865813 | B46: FERNANDA LUZ ORTIZ VELIZ
A47: 12912271 | B47: RODRIGO ALFONSO ALARCON CORRALES
A48: 12963368 | B48: PABLO ANDRES CONTRERAS VASQUEZ
A49: 13099763 | B49: JOSE MANUEL ARIAS MEJIAS
A50: 13100069 | B50: CARLOS ECHAGUE PAVEZ
A51: 13100102 | B51: AMERICO ZUÑIGA
A52: 13346006 | B52: JUAN PABLO REYES FUENTES
A53: 13375769 | B53: FARY ENOC PARADA VARGAS
A54: 13476990 | B54: MARCELA JORQUERA OYARCE
A55: 13501829 | B55: LUIS HERNAN NUNEZ MORA
...
